<?xml version="1.0"?>
<robot name="denso" xmlns:xacro="http://www.ros.org/wiki/xacro">

    <xacro:include filename="/urdf/materials.xacro" />
    <xacro:include filename="/urdf/denso.ros2control.xacro" />
    <xacro:include filename="/urdf/denso.gazebo" />
    <link name="base_link">
        <inertial>
            <origin xyz="0.050675313846172125 0.006461713897883088 0.08287282171007057" rpy="0 0 0" />
            <mass value="6.143539323804497" />
            <inertia ixx="0.025465" iyy="0.052723" izz="0.0493" ixy="-0.002444" iyz="0.000346"
                ixz="0.002582" />
        </inertial>
        <visual>
            <origin xyz="0 0 0" rpy="0 0 0" />
            <geometry>
                <mesh filename="file:///meshes/base_link.stl" scale="0.001 0.001 0.001" />
            </geometry>
            <material name="silver" />
        </visual>
        <collision>
            <origin xyz="0 0 0" rpy="0 0 0" />
            <geometry>
                <mesh filename="file:///meshes/base_link.stl" scale="0.001 0.001 0.001" />
            </geometry>
        </collision>
    </link>

    <link name="J2">
        <inertial>
            <origin xyz="0.013120860228413238 0.08072874758443999 0.08272907608760566" rpy="0 0 0" />
            <mass value="3.463170121519725" />
            <inertia ixx="0.035685" iyy="0.032877" izz="0.010107" ixy="7e-06" iyz="-0.000994"
                ixz="-0.001271" />
        </inertial>
        <visual>
            <origin xyz="0.0 0.0765 -0.341" rpy="0 0 0" />
            <geometry>
                <mesh filename="file:///meshes/J2.stl" scale="0.001 0.001 0.001" />
            </geometry>
            <material name="silver" />
        </visual>
        <collision>
            <origin xyz="0.0 0.0765 -0.341" rpy="0 0 0" />
            <geometry>
                <mesh filename="file:///meshes/J2.stl" scale="0.001 0.001 0.001" />
            </geometry>
        </collision>
    </link>

    <link name="J3">
        <inertial>
            <origin xyz="-0.03190268879321906 0.0678908823505171 0.0038087594761062604" rpy="0 0 0" />
            <mass value="1.4837439572080482" />
            <inertia ixx="0.002236" iyy="0.004408" izz="0.004488" ixy="3.7e-05" iyz="-6e-06"
                ixz="0.000266" />
        </inertial>
        <visual>
            <origin xyz="0.0 0.0675 -0.591" rpy="0 0 0" />
            <geometry>
                <mesh filename="file:///meshes/J3.stl" scale="0.001 0.001 0.001" />
            </geometry>
            <material name="silver" />
        </visual>
        <collision>
            <origin xyz="0.0 0.0675 -0.591" rpy="0 0 0" />
            <geometry>
                <mesh filename="file:///meshes/J3.stl" scale="0.001 0.001 0.001" />
            </geometry>
        </collision>
    </link>

    <link name="J4">
        <inertial>
            <origin xyz="-0.07553858060026801 -0.002145972351478621 0.0009839741900651289"
                rpy="0 0 0" />
            <mass value="0.996038199129269" />
            <inertia ixx="0.001533" iyy="0.002708" izz="0.003096" ixy="-7.4e-05" iyz="8e-06"
                ixz="-3e-06" />
        </inertial>
        <visual>
            <origin xyz="0.105 -0.004 -0.601" rpy="0 0 0" />
            <geometry>
                <mesh filename="file:///meshes/J4.stl" scale="0.001 0.001 0.001" />
            </geometry>
            <material name="silver" />
        </visual>
        <collision>
            <origin xyz="0.105 -0.004 -0.601" rpy="0 0 0" />
            <geometry>
                <mesh filename="file:///meshes/J4.stl" scale="0.001 0.001 0.001" />
            </geometry>
        </collision>
    </link>

    <link name="J1">
        <inertial>
            <origin xyz="-0.005438018755668024 -0.009336366454460655 0.1089556893220168" rpy="0 0 0" />
            <mass value="2.0347620188411075" />
            <inertia ixx="0.016049" iyy="0.012314" izz="0.008982" ixy="-0.000125" iyz="0.000902"
                ixz="-2.1e-05" />
        </inertial>
        <visual>
            <origin xyz="0.0 -0.004 -0.1445" rpy="0 0 0" />
            <geometry>
                <mesh filename="file:///meshes/J1.stl" scale="0.001 0.001 0.001" />
            </geometry>
            <material name="silver" />
        </visual>
        <collision>
            <origin xyz="0.0 -0.004 -0.1445" rpy="0 0 0" />
            <geometry>
                <mesh filename="file:///meshes/J1.stl" scale="0.001 0.001 0.001" />
            </geometry>
        </collision>
    </link>

    <link name="J5">
        <inertial>
            <origin xyz="-0.011532157477539884 0.03602680320910975 -0.0011494913532542617"
                rpy="0 0 0" />
            <mass value="0.4356284491248545" />
            <inertia ixx="0.000306" iyy="0.000599" izz="0.000526" ixy="3e-06" iyz="1e-06"
                ixz="-1e-06" />
        </inertial>
        <visual>
            <origin xyz="0.255 0.0325 -0.601" rpy="0 0 0" />
            <geometry>
                <mesh filename="file:///meshes/J5.stl" scale="0.001 0.001 0.001" />
            </geometry>
            <material name="silver" />
        </visual>
        <collision>
            <origin xyz="0.255 0.0325 -0.601" rpy="0 0 0" />
            <geometry>
                <mesh filename="file:///meshes/J5.stl" scale="0.001 0.001 0.001" />
            </geometry>
        </collision>
    </link>

    <link name="J6">
        <inertial>
            <origin xyz="-0.0035989683250183258 2.362398471289495e-13 0.00023103660352374877"
                rpy="0 0 0" />
            <mass value="0.010931367282075048" />
            <inertia ixx="4e-06" iyy="2e-06" izz="2e-06" ixy="-0.0" iyz="-0.0" ixz="0.0" />
        </inertial>
        <visual>
            <origin xyz="0.323 -0.004 -0.601" rpy="0 0 0" />
            <geometry>
                <mesh filename="file:///meshes/J6.stl" scale="0.001 0.001 0.001" />
            </geometry>
            <material name="silver" />
        </visual>
        <collision>
            <origin xyz="0.323 -0.004 -0.601" rpy="0 0 0" />
            <geometry>
                <mesh filename="file:///meshes/J6.stl" scale="0.001 0.001 0.001" />
            </geometry>
        </collision>
    </link>

    <joint name="joint_1" type="revolute">
        <origin xyz="0.0 0.004 0.1445" rpy="0 0 0" />
        <parent link="base_link" />
        <child link="J1" />
        <axis xyz="-0.0 -0.0 1.0" />
        <limit effort="1" lower="-2.96705972839036" upper="2.96705972839036"
            velocity="3.73064127613788" />
        <dynamics damping="0" friction="0" />
    </joint>

    <joint name="joint_2" type="revolute">
        <origin xyz="0.0 -0.0805 0.1965" rpy="0 0 0" />
        <parent link="J1" />
        <child link="J2" />
        <axis xyz="-0.0 1.0 -0.0" />
        <limit upper="2.094395" lower="-2.094395" effort="1" velocity="2.48709418409192" />
        <dynamics damping="0" friction="0" />
    </joint>

    <joint name="joint_3" type="revolute">
        <origin xyz="0.0 0.009 0.25" rpy="0 0 0" />
        <parent link="J2" />
        <child link="J3" />
        <axis xyz="-0.0 1.0 -0.0" />
        <limit lower="-2.0943951024" upper="2.6354471705" effort="1" velocity="2.71540943019156" />
        <dynamics damping="0" friction="0" />
    </joint>

    <joint name="joint_4" type="revolute">
        <origin xyz="-0.105 0.0715 0.01" rpy="0 0 0" />
        <parent link="J3" />
        <child link="J4" />
        <axis xyz="-1.0 -0.0 -0.0" />
        <limit effort="1" lower="-4.71238898038469" upper="4.71238898038469"
            velocity="3.73064127613788" />
        <dynamics damping="0" friction="0" />
    </joint>

    <joint name="joint_5" type="revolute">
        <origin xyz="-0.15 -0.0365 0.0" rpy="0 0 0" />
        <parent link="J4" />
        <child link="J5" />
        <axis xyz="-0.0 1.0 0.0" />
        <limit upper="2.094395" lower="-2.094395" effort="1" velocity="2.87060410727889" />
    </joint>

    <joint name="joint_6" type="revolute">
        <origin xyz="-0.068 0.0365 0.0" rpy="0 0 0" />
        <parent link="J5" />
        <child link="J6" />
        <axis xyz="-1.0 -0.0 0.0" />
        <limit effort="1" lower="-6.28318530717959" upper="6.28318530717959"
            velocity="5.96902604182061" />
        <dynamics damping="0" friction="0" />
    </joint>

</robot>