<mujoco model="denso">
    <compiler angle="radian" />

    <asset>
        <mesh name="base_link" file="base_link.stl" scale="0.001 0.001 0.001" />
        <mesh name="J2" file="J2.stl" scale="0.001 0.001 0.001" />
        <mesh name="J3" file="J3.stl" scale="0.001 0.001 0.001" />
        <mesh name="J4" file="J4.stl" scale="0.001 0.001 0.001" />
        <mesh name="J1" file="J1.stl" scale="0.001 0.001 0.001" />
        <mesh name="J5" file="J5.stl" scale="0.001 0.001 0.001" />
        <mesh name="J6" file="J6.stl" scale="0.001 0.001 0.001" />
    </asset>

    <worldbody>
        <geom type="mesh" mesh="base_link" />
        <body name="J1" pos="0 0.004 0.1445">
            <inertial pos="-0.00543802 -0.00933637 0.108956"
                quat="0.99215 0.123755 0.00152193 -0.017931" mass="2.03476"
                diaginertia="0.0160536 0.012538 0.00875348" />
            <joint name="joint_1" pos="0 0 0" axis="0 0 1" range="-2.96706 2.96706"
                actuatorfrcrange="-1 1" />
            <geom pos="0 -0.004 -0.1445" type="mesh" mesh="J1" />
            <body name="J2" pos="0 -0.0805 0.1965">
                <inertial pos="0.0131209 0.0807287 0.0827291"
                    quat="0.999405 -0.0214235 0.0249224 0.0104547" mass="3.46317"
                    diaginertia="0.0357491 0.0329189 0.0100009" />
                <joint name="joint_2" pos="0 0 0" axis="0 1 0" range="-2.0944 2.0944"
                    actuatorfrcrange="-1 1" />
                <geom pos="0 0.0765 -0.341" type="mesh" mesh="J2" />
                <body name="J3" pos="0 0.009 0.25">
                    <inertial pos="-0.0319027 0.0678909 0.00380876"
                        quat="0.0012934 0.746817 -0.0113232 0.664932" mass="1.48374"
                        diaginertia="0.00451902 0.00440861 0.00220437" />
                    <joint name="joint_3" pos="0 0 0" axis="0 1 0" range="-2.0944 2.63545"
                        actuatorfrcrange="-1 1" />
                    <geom pos="0 0.0675 -0.591" quat="1 0 0 0" type="mesh" mesh="J3" />
                    <body name="J4" pos="-0.105 0.0715 0.01">
                        <inertial pos="-0.0755386 -0.00214597 0.000983974"
                            quat="-0.0146242 0.705922 0.0296457 0.707518" mass="0.996038"
                            diaginertia="0.00309618 0.00271247 0.00152835" />
                        <joint name="joint_4" pos="0 0 0" axis="-1 0 0" range="-4.71239 4.71239"
                            actuatorfrcrange="-1 1" />
                        <geom pos="0.105 -0.004 -0.601" quat="1 0 0 0" type="mesh" mesh="J4" />
                        <body name="J5" pos="-0.15 -0.0365 0">
                            <inertial pos="-0.0115322 0.0360268 -0.00114949"
                                quat="0.50032 0.504752 0.492879 0.501972" mass="0.435628"
                                diaginertia="0.000599044 0.000525991 0.000305965" />
                            <joint name="joint_5" pos="0 0 0" axis="0 1 0" range="-2.0944 2.0944"
                                actuatorfrcrange="-1 1" />
                            <geom pos="0.255 0.0325 -0.601" quat="1 0 0 0" type="mesh" mesh="J5" />
                            <body name="J6" pos="-0.068 0.0365 0">
                                <inertial pos="-0.00359897 0 0.000231037" mass="0.0109314"
                                    diaginertia="4e-06 2e-06 2e-06" />
                                <joint name="joint_6" pos="0 0 0" axis="-1 0 0"
                                    range="-6.28319 6.28319" actuatorfrcrange="-1 1" />
                                <geom pos="0.323 -0.004 -0.601" type="mesh" mesh="J6" />
                            </body>
                        </body>
                    </body>
                </body>
            </body>
        </body>
    </worldbody>
    <actuator>
        <position name="joint_1" joint="joint_1" ctrllimited="true" ctrlrange="-1 1" kp="10" kv="10" />
        <position name="joint_2" joint="joint_2" ctrllimited="true" ctrlrange="-1 1" kp="10" kv="10" />
        <position name="joint_3" joint="joint_3" ctrllimited="true" ctrlrange="-1 1" kp="10" kv="10" />
        <position name="joint_4" joint="joint_4" ctrllimited="true" ctrlrange="-1 1" kp="10" kv="10" />
        <position name="joint_5" joint="joint_5" ctrllimited="true" ctrlrange="-1 1" kp="10" kv="10" />
        <position name="joint_6" joint="joint_6" ctrllimited="true" ctrlrange="-1 1" kp="10" kv="10" />
    </actuator>
</mujoco>